Workbook

Sheet Assessment Overview
A1: FedRAMP 20x Assessment Overview
A2: Meridian Knowledge Systems MKS
A5: ASSESSMENT INFORMATION
A6: Assessor: | B6: Fortreum LLC | E6: Assessment Type: | F6: Initial Assessment
A7: Client: | B7: Meridian Knowledge Systems | E7: System: | F7: MKS
A8: Period: | B8: 2025-05-20 to 2025-06-06 | E8: Scope: | F8: All KSI, and All MAS Requirements
A10: KEY SECURITY INDICATORS
A11: FedRAMP Key Security Indicators (KSIs) summarize the capabilities that satisfy FedRAMP security requirements aligned to NIST SP 800-53. Each Key Security Indicator includes critical security capabilities that must be met and validated. These capabilities are designed to provide a concrete approach to evaluating cloud security risks that can often be derived automatically from technical configurations.
A12: The following rules ALWAYS apply to ALL FedRAMP 20x authorizations:
A13: FRR-KSI-01: Cloud service providers MUST apply ALL Key Security Indicators to ALL aspects of their cloud service offering that are within the FedRAMP Minimum Assessment Scope.
A14: The following rules provide general guidance on the application of Key Security Indicators:
A15: FRR-KSI-AY-01: All parties SHOULD follow FedRAMP's best practices and technical assistance on assessing Key Security Indicators where applicable.
A16: FRR-KSI-AY-02: (INTERIM RULE) All parties SHOULD continuously monitor and review materials in the FedRAMP 20x Phase One (20xP1) pilot requirements and the 20x Community Working Group. Additional details, interim best practices and technical assistance, answers to common questions, and more will be provided asynchronously during 20xP1.
A18: KSI COMPLIANCE SUMMARY
A19: KSI ID | B19: KSI Name | C19: Total Requirements | D19: Requirements Met | E19: Requirements Partially Met | F19: Requirements Not Met | G19: Overall Status | H19: Automation Status | I19: Mitigation Required
A20: KSI-CNA | B20: Cloud Native Architecture | C20: =COUNTIFS('KSI Requirements'!A:A,"KSI-CNA") -> 7 | D20: =COUNTIFS('KSI Requirements'!A:A,"KSI-CNA", 'KSI Requirements'!H:H, TRUE) -> 5 | E20: =COUNTIFS('KSI Requirements'!A:A,"KSI-CNA", 'KSI Requirements'!H:H, "PARTIAL") -> 2 | F20: =COUNTIFS('KSI Requirements'!A:A,"KSI-CNA", 'KSI Requirements'!H:H, FALSE) -> 0 | G20: 0.93 | H20: ='KSI Assessment Details'!H4 -> Fully Automated | I20: No
A21: KSI-SVC | B21: Service Configuration | C21: =COUNTIFS('KSI Requirements'!A:A,"KSI-SVC") -> 7 | D21: =COUNTIFS('KSI Requirements'!A:A,"KSI-SVC", 'KSI Requirements'!H:H, TRUE) -> 7 | E21: =COUNTIFS('KSI Requirements'!A:A,"KSI-SVC", 'KSI Requirements'!H:H, "PARTIAL") -> 0 | F21: =COUNTIFS('KSI Requirements'!A:A,"KSI-SVC", 'KSI Requirements'!H:H, FALSE) -> 0 | G21: 0.78 | H21: ='KSI Assessment Details'!H5 -> Fully Automated | I21: Partial
A22: KSI-IAM | B22: Identity and Access Management | C22: =COUNTIFS('KSI Requirements'!A:A,"KSI-IAM") -> 6 | D22: =COUNTIFS('KSI Requirements'!A:A,"KSI-IAM", 'KSI Requirements'!H:H, TRUE) -> 6 | E22: =COUNTIFS('KSI Requirements'!A:A,"KSI-IAM", 'KSI Requirements'!H:H, "PARTIAL") -> 0 | F22: =COUNTIFS('KSI Requirements'!A:A,"KSI-IAM", 'KSI Requirements'!H:H, FALSE) -> 0 | G22: 1 | H22: ='KSI Assessment Details'!H6 -> Fully Automated | I22: No
A23: KSI-MLA | B23: Monitoring, Logging, and Auditing | C23: =COUNTIFS('KSI Requirements'!A:A,"KSI-MLA") -> 6 | D23: =COUNTIFS('KSI Requirements'!A:A,"KSI-MLA", 'KSI Requirements'!H:H, TRUE) -> 5 | E23: =COUNTIFS('KSI Requirements'!A:A,"KSI-MLA", 'KSI Requirements'!H:H, "PARTIAL") -> 1 | F23: =COUNTIFS('KSI Requirements'!A:A,"KSI-MLA", 'KSI Requirements'!H:H, FALSE) -> 0 | G23: 0.92 | H23: ='KSI Assessment Details'!H7 -> Fully Automated | I23: Partial
A24: KSI-CMT | B24: Change Management | C24: =COUNTIFS('KSI Requirements'!A:A,"KSI-CMT") -> 5 | D24: =COUNTIFS('KSI Requirements'!A:A,"KSI-CMT", 'KSI Requirements'!H:H, TRUE) -> 4 | E24: =COUNTIFS('KSI Requirements'!A:A,"KSI-CMT", 'KSI Requirements'!H:H, "PARTIAL") -> 1 | F24: =COUNTIFS('KSI Requirements'!A:A,"KSI-CMT", 'KSI Requirements'!H:H, FALSE) -> 0 | G24: 0.9 | H24: ='KSI Assessment Details'!H8 -> Partially Automated | I24: Partial
A25: KSI-PIY | B25: Policy and Inventory | C25: =COUNTIFS('KSI Requirements'!A:A,"KSI-PIY") -> 7 | D25: =COUNTIFS('KSI Requirements'!A:A,"KSI-PIY", 'KSI Requirements'!H:H, TRUE) -> 5 | E25: =COUNTIFS('KSI Requirements'!A:A,"KSI-PIY", 'KSI Requirements'!H:H, "PARTIAL") -> 2 | F25: =COUNTIFS('KSI Requirements'!A:A,"KSI-PIY", 'KSI Requirements'!H:H, FALSE) -> 0 | G25: 0.96 | H25: ='KSI Assessment Details'!H9 -> Partially Automated | I25: Partial
A26: KSI-TPR | B26: Third-Party Information Resources | C26: =COUNTIFS('KSI Requirements'!A:A,"KSI-TPR") -> 4 | D26: =COUNTIFS('KSI Requirements'!A:A,"KSI-TPR", 'KSI Requirements'!H:H, TRUE) -> 3 | E26: =COUNTIFS('KSI Requirements'!A:A,"KSI-TPR", 'KSI Requirements'!H:H, "PARTIAL") -> 1 | F26: =COUNTIFS('KSI Requirements'!A:A,"KSI-TPR", 'KSI Requirements'!H:H, FALSE) -> 0 | G26: 0.88 | H26: ='KSI Assessment Details'!H10 -> Partially Automated | I26: No
A27: KSI-CED | B27: Cybersecurity Education | C27: =COUNTIFS('KSI Requirements'!A:A,"KSI-CED") -> 2 | D27: =COUNTIFS('KSI Requirements'!A:A,"KSI-CED", 'KSI Requirements'!H:H, TRUE) -> 2 | E27: =COUNTIFS('KSI Requirements'!A:A,"KSI-CED", 'KSI Requirements'!H:H, "PARTIAL") -> 0 | F27: =COUNTIFS('KSI Requirements'!A:A,"KSI-CED", 'KSI Requirements'!H:H, FALSE) -> 0 | G27: 1 | H27: ='KSI Assessment Details'!H11 -> Manual | I27: No
A28: KSI-RPL | B28: Recovery Planning | C28: =COUNTIFS('KSI Requirements'!A:A,"KSI-RPL") -> 4 | D28: =COUNTIFS('KSI Requirements'!A:A,"KSI-RPL", 'KSI Requirements'!H:H, TRUE) -> 2 | E28: =COUNTIFS('KSI Requirements'!A:A,"KSI-RPL", 'KSI Requirements'!H:H, "PARTIAL") -> 2 | F28: =COUNTIFS('KSI Requirements'!A:A,"KSI-R{:", 'KSI Requirements'!H:H, FALSE) -> 0 | G28: 0.75 | H28: ='KSI Assessment Details'!H12 -> Partially Automated | I28: No
A29: KSI-INR | B29: Incident Reporting | C29: =COUNTIFS('KSI Requirements'!A:A,"KSI-INR") -> 3 | D29: =COUNTIFS('KSI Requirements'!A:A,"KSI-INR", 'KSI Requirements'!H:H, TRUE) -> 3 | E29: =COUNTIFS('KSI Requirements'!A:A,"KSI-INR", 'KSI Requirements'!H:H, "PARTIAL") -> 0 | F29: =COUNTIFS('KSI Requirements'!A:A,"KSI-INR", 'KSI Requirements'!H:H, FALSE) -> 0 | G29: 1 | H29: ='KSI Assessment Details'!H13 -> Partially Automated | I29: No
A32: OVERALL ASSESSMENT RESULTS
A33: Total KSIs Assessed: | C33: =SUM(C20:C29) -> 51
A34: KSIs Met: | C34: =SUM(D20:D29) -> 42
A35: KSIs Partially Met: | C35: =SUM(E20:E29) -> 9
A36: KSIs Not Met: | C36: 0
A37: Overall Compliance: | C37: 0.8922
A38: Automation Level: | C38: 0.7451
A39: Total Requirements: | C39: 51

Sheet KSI Assessment Details
A1: Key Security Indicators - Detailed Assessment
A3: KSI Domain | B3: KSI ID | C3: KSI Name | D3: KSI Description | E3: Assessment Objective | F3: Test Method | G3: Automated Validation Tools | H3: Automation Status | I3: Observations/Test Results | J3: Evidence | K3: Met & Validated | L3: Recommendation for Mitigation
A4: Cloud Native Architecture | B4: KSI-CNA | C4: Cloud Native Architecture | D4: A secure cloud service offering will use cloud native architecture and design principles to enforce and enhance the Confidentiality, Integrity and Availability of the system. | E4: Verify Command Center implements cloud native architecture with proper network segmentation, immutable infrastructure, and high availability | F4: The KSI-CNA testing methods are outlined in the KSI Requirements tab of this workbook. These details specify the Fortreum assessment decisions for this KSI objective. | G4: AWS GuardDuty, AWS CloudFront, AWS Systems Manager, AWS Route Tables, AWS WAF, Amazon, EC2 Snapshots, Elastic Load Balancing, IAM Access Analyzer, VPC Network ACLs, VPC Security Groups, AWS VPC Flow Logs, AWS CloudWatch, AWS Lambda, AWS Route 53, AWS Autoscaling, AWS DynamoDB, AWS CodeBuilds, AWS SSM, AWS Backup, AWS Congig https://meridian-knowledge-solutions.github.io/fedramp_20x_public_submission_live/ | H4: Fully Automated | I4: Determination: Based on the comprehensive automation results across multiple categories, the environment demonstrates a strong adherence to AWS best practices and security principles. The infrastructure exhibits robust multi-layer traffic controls, effective ingress restrictions, and well-managed egress through NAT gateways and VPC endpoints. Logical networking is intentionally designed with advanced routing, segmentation, and traffic flow monitoring. The architecture minimizes attack surfaces and lateral movement through private subnets, custom security groups, and isolated services. High availability is ensured via multi-AZ deployments, resilient DNS, and backup strategies. The environment is fully managed through Terraform, promoting immutability and consistency, and includes comprehensive DoS protection with AWS Shield and WAF. Governance and compliance are well-supported with CloudTrail, KMS encryption, IAM best practices, and AWS Config readiness. Overall, the environment is well-architected, secure, resilient, and operationally mature, making it suitable for production-grade workloads or pilot deployments with minimal risk. | J4: 1. failed_ksi_Report_readable.md (git/validation folder) 2. continuous_ksi_results.json (git/results folder) 3, ksi_rules:KSI-CNA.01.md (docs/ksi_rules) 4. KSI-CNA.01-cli_output.json (KSI-CNA.01) 5. ksi_rules:KSI-CNA.02.md (docs/ksi_rules) 6. KSI-CNA.02-cli_output.json (KSI-CNA.02) 7. ksi_rules:KSI-CNA.03.md (docs/ksi_rules) 8. KSI-CNA.03-cli_output.json (KSI-CNA.03) 9. ksi_rules:KSI-CNA.04.md (docs/ksi_rules) 10. KSI-CNA.04-cli_output.json (KSI-CNA.04) 11. ksi_rules:KSI-CNA.05.md (docs/ksi_rules) 12. KSI-CNA.05-cli_output.json (KSI-CNA.05) 13. ksi_rules:KSI-CNA.06.md (docs/ksi_rules) 14. KSI-CNA.06-cli_output.json (KSI-CNA.06) 15. ksi_rules:KSI-CNA.07.md (docs/ksi_rules) 16. KSI-CNA.07-cli_output.json (KSI-CNA.07) | K4: Partial | L4: N/A - All requirements met
A5: Service Configuration | B5: KSI-SVC | C5: Service Configuration | D5: A secure cloud service offering will follow FedRAMP encryption policies, continuously verify information resource integrity, and restrict access to third-party information resources. | E5: Verify proper encryption implementation, configuration management, and security hardening across Command Center services | F5: The KSI-SVC testing methods are detailed in the KSI Requirements tab of this workbook. Those details specify the Fortreum assessment decisions related to this KSI objective. | G5: AWS Organizations, AWS GuardDuty, AWS CloudFront, AWS CloudFormation, AWS Systems Manager, AWS SecretsManager, AWS WAF, Amazon, EC2 Snapshots, Elastic Load Balancing, AWS CloudWatch, AWS CloudTrail, AWS KMS, AWS ACM, AWS IAM, AWS Config, AWS Inspector, AWS ECR, AWS Lambda https://meridian-knowledge-solutions.github.io/fedramp_20x_public_submission_live/ | H5: Fully Automated | I5: Determination: Meridian has a production-ready security posture across multiple domains, with strong system hardening, encryption, and governance. It features multi-layer defenses like security groups, centralized patch management, and threat detection. Encryption covers storage, databases, backups, and communication, supported by automated certificate management via AWS KMS and ACM. Configuration management uses AWS SSM, CloudFormation, and centralized secrets. Governance is enforced through AWS Organizations and SCPs, ensuring consistency. Some areas like real-time monitoring and vulnerability patching could improve, but the environment is secure, scalable, and compliant. | J5: 1. failed_ksi_Report_readable.md (git/validation folder) 2. continuous_ksi_results.json (git/results folder) 3. ksi_rules:KSI-SVC.01.md (docs/ksi_rules) 4. KSI-SVC.01-cli_output.json (KSI-SVC.01) 5. ksi_rules:KSI-SVC.02.md (docs/ksi_rules) 6. KSI-SVC.02-cli_output.json (KSI-SVC.02) 7. ksi_rules:KSI-SVC.03.md (docs/ksi_rules) 8. KSI-SVC.03-cli_output.json (KSI-SVC.03) 9. ksi_rules:KSI-SVC.04.md (docs/ksi_rules) 10. KSI-SVC.04-cli_output.json (KSI-SVC.04) 11. ksi_rules:KSI-SVC.05.md (docs/ksi_rules) 12. KSI-SVC.05-cli_output.json (KSI-SVC.05) 13. ksi_rules:KSI-SVC.06.md (docs/ksi_rules) 14. KSI-SVC.06-cli_output.json (KSI-SVC.06) 15. ksi_rules:KSI-SVC.7.md (docs/ksi_rules) 16. KSI-SVC.7-cli_output.json (KSI-SVC.7) | K5: TRUE | L5: WARNING Instances registered with SSM but none online EC2 instances are successfully registered with AWS Systems Manager (SSM), they are currently not in a state where they can be managed or accessed through SSM. This typically means that the instances appear in the Systems Manager console, but they are not actively communicating with the SSM service. Fortreum views this as a configuration issue and not a risk.
A6: Identity and Access Management | B6: KSI-IAM | C6: Identity and Access Management | D6: A secure cloud service offering will protect user data, control access, and apply zero trust principles. | E6: Validate implementation of MFA, least privilege access, and zero trust principles in Command Center | F6: The KSI-IAM testing methods are detailed in the KSI Requirements tab of this workbook. These details specify the Fortreum assessment decisions for this KSI objective. | G6: API Gateway, AWS WAF, AWS WorkSpaces, Active Directory GPO, Amazon Cognito, Command Center KSI-IAM Lambda, S3 Policy Storage https://meridian-knowledge-solutions.github.io/fedramp_20x_public_submission_live/ | H6: Fully Automated | I6: Determination: Meridian reflects a secure and modern identity and access management framework. It uses IAM Identity Center with full Okta federation, enforcing passwordless authentication and upstream MFA. The Okta version is phishing-resistant. Access is tightly controlled through role-based permission sets and temporary credentials. Traditional IAM usage is minimal and limited to service accounts. Security is further enhanced with GuardDuty, Security Hub, and automated response via EventBridge and Lambda. These controls support zero trust principles and ensure strong identity governance, authentication, and automated security enforcement across services. | J6: 1. failed_ksi_Report_readable.md (git/validation folder) 2. continuous_ksi_results.json (git/results folder) 3. ksi_rules:KSI-IAM.01.md (docs/ksi_rules) 4. KSI-IAM.01-cli_output.json (KSI-IAM.01) 5. ksi_rules:KSI-IAM.02.md (docs/ksi_rules) 6. KSI-IAM.02-cli_output.json (KSI-IAM.02) 7. ksi_rules:KSI-IAM.03.md (docs/ksi_rules) 8. KSI-IAM.03-cli_output.json (KSI-IAM.03) 9. ksi_rules:KSI-IAM.04.md (docs/ksi_rules) 10. KSI-IAM.04-cli_output.json (KSI-IAM.04) 11. ksi_rules:KSI-IAM.05.md (docs/ksi_rules) 12. KSI-IAM.05-cli_output.json (KSI-IAM.05) 13. ksi_rules:KSI-IAM.06.md (docs/ksi_rules) 14. KSI-IAM.06-cli_output.json (KSI-IAM.06) | K6: TRUE | L6: N/A - All requirements met
A7: Monitoring, Logging, and Auditing | B7: KSI-MLA | C7: Monitoring, Logging, and Auditing | D7: A secure cloud service offering will monitor, log, and audit all important events, activity, and changes. | E7: Verify comprehensive monitoring, centralized logging, and vulnerability management capabilities | F7: The KSI-MLA testing methods are detailed in the KSI Requirements tab of this workbook. These details specify the Fortreum assessment decisions for this KSI objective. | G7: AWS GuardDuty, AWS IAM, AWS SSO, AWS IdentityStore, AWS EC2, AWS CloudWatch, AWS CloudTrail, AWS SecurityHub, AWS Lambda, AWS Config. https://meridian-knowledge-solutions.github.io/fedramp_20x_public_submission_live/ | H7: Fully Automated | I7: Determination: Meridian demonstrates strong monitoring and logging capabilities aligned with enterprise security standards. CloudTrail and AWS Config provide audit and configuration tracking, while centralized log collection spans multiple services and applications with defined retention policies. Security Hub and Inspector enable advanced threat and vulnerability detection, supported by automated findings, insights, and remediation workflows. SNS topics and EventBridge rules facilitate alerting and response, though some areas like CloudWatch alarms and automated pipelines could be expanded. Overall, the environment supports effective SIEM operations, vulnerability management, and compliance monitoring across accounts. | J7: 1. failed_ksi_Report_readable.md (git/validation folder) 2. continuous_ksi_results.json (git/results folder) 3. ksi_rules:KSI-MLA.01.md (docs/ksi_rules) 4. KSI-MLA.01-cli_output.json (KSI-MLA.01) 5. ksi_rules:KSI-MLA.02.md (docs/ksi_rules) 6. KSI-MLA.02-cli_output.json (KSI-MLA.02) 7. ksi_rules:KSI-MLA.03.md (docs/ksi_rules) 8. KSI-MLA.03-cli_output.json (KSI-MLA.03) 9. ksi_rules:KSI-MLA.04.md (docs/ksi_rules) 10. KSI-MLA.04-cli_output.json (KSI-MLA.04) 11. ksi_rules:KSI-MLA.05.md (docs/ksi_rules) 12. KSI-MLA.05-cli_output.json (KSI-MLA.05) 13. ksi_rules:KSI-MLA.06.md (docs/ksi_rules) 14. KSI-MLA.06-cli_output.json (KSI-MLA.06) | K7: Partial | L7: WARNING Instances registered with SSM but none online EC2 instances are successfully registered with AWS Systems Manager (SSM), they are currently not in a state where they can be managed or accessed through SSM. This typically means that the instances appear in the Systems Manager console, but they are not actively communicating with the SSM service. Fortreum views this as a configuration issue and not a risk. WARNING No Config rules for infrastructure evaluation AWS Config is enabled in the MKS account, but there are currently no active Config rules set up to evaluate the compliance of the MKS infrastructure resources. AWS Config is a service that continuously monitors and records your AWS resource configurations and allows you to assess them against desired configurations using rules. Fortreum recommends that Meridian work to enable the config rules to evaluate the MKS resources.
A8: Change Management | B8: KSI-CMT | C8: Change Management | D8: A secure cloud service provider will ensure that all system changes are properly documented and configuration baselines are updated accordingly. | E8: Verify change management processes, configuration control, and security impact assessments | F8: The KSI-CMT testing methods are described in the KSI Requirements tab of this workbook. Those details specify the Fortreum assessment decisions for this KSI objective. | G8: AWS Config, AWS CloudWatch, AWS CloudTrail, AWS SSM, AWS Security Hub, Amazon ECR, AWS Config, AWS ELB, AWS Organizations https://meridian-knowledge-solutions.github.io/fedramp_20x_public_submission_live/ | H8: Partially Automated | I8: Determination: Meridian demonstrates strong configuration management practices. CloudFormation and SSM enforce consistent infrastructure and parameter baselines, while AWS Config records system changes. CloudTrail and SNS support change tracking and alerting. Immutable deployment is partially implemented, with room to expand coverage. Centralized governance via AWS Organizations and SCPs ensures policy enforcement across accounts. | J8: 1. failed_ksi_Report_readable.md (git/validation folder) 2. continuous_ksi_results.json (git/results folder) 3. ksi_rules:KSI-CMT.01.md (docs/ksi_rules) 4. KSI-CMT.01-cli_output.json (KSI-CMT.01) 5. ksi_rules:KSI-CMT.02.md (docs/ksi_rules) 6. KSI-CMT.02-cli_output.json (KSI-CMT.02) 7. ksi_rules:KSI-CMT.03.md (docs/ksi_rules) 8. KSI-CMT.03-cli_output.json (KSI-CMT.03) 9. ksi_rules:KSI-CMT.04.md (docs/ksi_rules) 10. KSI-CMT.04-cli_output.json (KSI-CMT.04) 11. ksi_rules:KSI-CMT.05.md (docs/ksi_rules) 12. KSI-CMT.05-cli_output.json (KSI-CMT.05) 13. automated_testing_proof.json (KSI-CMT.03) 14. Chedkov_scan_summary.json (KSI-CMT.03) 15. configuration_management_plan (KSI-CMT.04) 16. configuration_management_policy_and_procedures (KSI-CMT.04) 17. weekly_change_management_meeting_final.png (KSI-CMT.04) 18. Change Impact Analysis Template (KSI-CMT-05) 19. Risk Assessment Procedure for Change Management (KSI-CMT-05) | K8: TRUE | L8: WARNING No launch templates for immutable instance deployment The MKS environment is not using launch templates to manage EC2 instance configurations, which is a recommended best practice for implementing immutable infrastructure. Fortreum recommends that Meridian work on the CI/CD development flow replacing instances entirely rather modifying them in place. As the environment is new, this considered to be a maturity of the SDLC practice. WARNING Lambda functions found but not using versioning for immutability AWS Lambda functions are deployed without using versioning, which is a key practice for maintaining immutable infrastructure. Fortreum recommends versioning Lambda functions to mature the development practice.
A9: Policy and Inventory | B9: KSI-PIY | C9: Policy and Inventory | D9: A secure cloud service offering will have intentional, organized, universal guidance for how every information resource, including personnel, is secured. | E9: Verify comprehensive inventory management, security policies, and organizational commitment | F9: The KSI-PIY testing methods are outlined in the KSI Requirements tab of this workbook. These details specify the Fortreum assessment decisions for this KSI objective. | G9: AWS CodeCommit, AWS Config, Command Center KSI-PIY Lambda, S3 Document Storage, S3 Documentation, S3 Policy Storage https://meridian-knowledge-solutions.github.io/fedramp_20x_public_submission_live/ | H9: Partially Automated | I9: Determination: Based on the KSI validation requirement, Fortreum determined that Meridian maintains a documented but partially automated approach to inventory, policy, and secure development. A tagged AWS resource inventory is supported by manual records, while security policies, SDLC procedures, and supply chain risk management are well-documented. Vulnerability disclosure and evaluation processes are in place, though integration with automated pipelines and source control is limited. Expanding automation and inventory coverage will enhance visibility, governance, and incident response. | J9: 1. failed_ksi_Report_readable.md (git/validation folder) 2. continuous_ksi_results.json (git/results folder) 3. ksi_rules:KSI-PIY.01.md (docs/ksi_rules) 4. KSI-PIY.01-cli_output.json (KSI-PIY.01) 5. ksi_rules:KSI-PIY.02.md (docs/ksi_rules) 6. KSI-PIY.02-cli_output.json (KSI-PIY.02) 7. ksi_rules:KSI-PIY.03.md (docs/ksi_rules) 8. KSI-PIY.03-cli_output.json (KSI-PIY.03) 9. ksi_rules:KSI-PIY.04.md (docs/ksi_rules) 10. KSI-PIY.04-cli_output.json (KSI-PIY.04) 11. ksi_rules:KSI-PIY.05.md (docs/ksi_rules) 12. KSI-PIY.05-cli_output.json (KSI-PIY.05) 13. ksi_rules:KSI-PIY.06.md (docs/ksi_rules) 14. KSI-PIY.06-cli_output.json (KSI-PIY.06) 15. ksi_rules:KSI-PIY.7.md (docs/ksi_rules) 16. KSI-PIY.7-cli_output.json (KSI-PIY.7) 17. data_classification_handling_policy (KSI-PIY.02) 18. personnel_security_policy (KSI-PIY.02) 19. security_policy_collection_repository.zip (KSI-PIY.02) 20. Information Resource Evaluation Methodology (KSI-PIY-05) 21. security_budget_allocation_and_roles (KSI-PIY.06) 22. Software Supply Chain Risk Management Framework (KSI-PIY-07) 23. Inspected weekly_change_management_meeting_final.png | K9: Partial | L9: WARNING Partial inventory coverage (expand documentation): PASS AWS resource inventory: 73 tagged resources discovered. Fortreum recommends fixing the AWS inventory rule. Reviewed the inventory manually. WARNING Basic secure development practices (expand documentation): INFO No CodeCommit repositories (may use external source control). Fortreum recommends maturing the development practice.
A10: Third-Party Information Resources | B10: KSI-TPR | C10: Third-Party Information Resources | D10: A secure cloud service offering will understand, monitor, and manage supply chain risks from third-party information resources. | E10: Verify third-party resource identification, FedRAMP compliance verification, and supply chain risk management | F10: The KSI-TPR testing methods are described in the KSI Requirements tab of this workbook. Those details explain the Fortreum assessment decisions for this KSI objective. | G10: AWS Config, AWS Organizations, Command Center KSI-TPR Lambda, Inspector, S3 Monitoring Evidence, S3 Risk Assessment Storage, S3 SBOM Storage, Security Hub https://meridian-knowledge-solutions.github.io/fedramp_20x_public_submission_live/ | H10: Partially Automated | I10: Determination: Based on the KSI validation requirement, Fortreum determined that Meridian demonstrates a structured approach to managing third-party and supply chain risks, with documented inventories and monitoring practices in place. A partial third-party inventory is supported by artifacts such as third_party_inventory.xlsx and sbom_including_elastic.json, although coverage should be expanded. FedRAMP authorization and secure configuration of federal data services are tracked through manual reviews and supporting documentation. Supply chain risk assessments, vendor attestations, and vulnerability monitoring are documented and actively maintained. Inspector findings confirm that contracts and notification agreements support the detection of third-party component vulnerabilities and upstream monitoring. While automation is limited, the foundation for secure third-party management is established, with opportunities to enhance visibility and integration. | J10: 1. failed_ksi_Report_readable.md (git/validation folder) 2. continuous_ksi_results.json (git/results folder) 3. ksi_rules:KSI-TPR.01.md (docs/ksi_rules) 4. KSI-TPR.01-cli_output.json (KSI-TPR.01) 5. ksi_rules:KSI-TPR.02.md (docs/ksi_rules) 6. KSI-TPR.02-cli_output.json (KSI-TPR.02) 7. ksi_rules:KSI-TPR.03.md (docs/ksi_rules) 8. KSI-TPR.03-cli_output.json (KSI-TPR.03) 9. ksi_rules:KSI-TPR.04.md (docs/ksi_rules) 10. KSI-TPR.04-cli_output.json (KSI-TPR.04) 11. FedRAMP_Low_Boundary_Diagram.pdf (KSI-TPR.02) 12. Federal Information Mapping - Meridian LMS.pdf(KSI-TPR.02) 13. Inspected Software Supply Chain Risk Management Framework (KSI-PIY-07) | K10: Partial | L10: N/A - All requirements met
A11: Cybersecurity Education | B11: KSI-CED | C11: Cybersecurity Education | D11: A secure cloud service provider will continuously educate their employees on cybersecurity measures, testing them regularly to ensure their knowledge is satisfactory. | E11: Verify comprehensive security training program for all employees and role-specific training | F11: The KSI-CED testing methods are outlined in the KSI Requirements tab of this workbook. Those details specify the Fortreum assessment decisions for this KSI objective. | G11: Manual Review KSI-CED-01 - cyber_security_Training.png - fedramp_role_based.png - security_training_roster.png https://meridian-knowledge-solutions.github.io/fedramp_20x_public_submission_live/ | H11: Manual | I11: Determination: Based on the KSI validation requirement, Fortreum determined that Meridian met the Cybersecurity Education requirement. | J11: 1. https://github.com/Meridian-Knowledge-Solutions/fedramp-20x-submission-final/tree/main/evidence_v2/KSI-CED-01 - cyber_security_Training.png - fedramp_role_based.png - security_training_roster.png 2. ksi_rules: KSI-CED.01.md (docs/ksi_rules) 3. Examined training records for Adam Bell, Adam Burroughs, Adrianna Bennett, Aubrey Zuro, Gabriel Crockett, Jake Silvers, James Hetzel, James Morris, Kirk Weir, Linda Sung, Quin Crease, Samuel Mbah, and Scott VanSooy. | K11: TRUE | L11: N/A - All requirements met
A12: Recovery Planning | B12: KSI-RPL | C12: Recovery Planning | D12: A secure cloud service offering will define, maintain, and test incident response plan(s) and recovery capabilities to ensure minimal service disruption and data loss during incidents and contingencies. | E12: Verify recovery objectives are defined, plans are maintained, and recovery capabilities are tested | F12: The KSI-RPL testing methods are outlined in the KSI Requirements tab of this workbook. These details specify the Fortreum assessment decisions for this KSI objective. | G12: AWS RDS, AWS Backup, AWS EC2 https://meridian-knowledge-solutions.github.io/fedramp_20x_public_submission_live/ | H12: Partially Automated | I12: Determination: Based on the KSI validation requirement, Fortreum determined that Meridian has a well-documented and technically validated approach to recovery planning, and resilience is necessary. RTO and RPO objectives are clearly defined and aligned with business impact analysis, supported by validated infrastructure configurations and backup plans. Recovery plans—including disaster recovery, incident response, and business continuity—are documented, maintained, and tested through tabletop exercises and restore operations. Testing results and lessons learned are reviewed to improve readiness. While some areas could benefit from deeper automation, the environment meets core recovery objectives and supports operational continuity through structured planning, regular testing, and validated backup infrastructure. | J12: 1. failed_ksi_Report_readable.md (git/validation folder) 2. continuous_ksi_results.json (git/results folder) 3. ksi_rules:KSI-RPL.01.md (docs/ksi_rules) 4. KSI-RPL.01-cli_output.json (KSI-RPL.01) 5. ksi_rules:KSI-RPL.02.md (docs/ksi_rules) 6. KSI-RPL.02-cli_output.json (KSI-RPL.02) 7. ksi_rules:KSI-RPL.03.md (docs/ksi_rules) 8. KSI-RPL.03-cli_output.json (KSI-RPL.03) 9. ksi_rules:KSI-RPL.04.md (docs/ksi_rules) 10. contingency plan test report (KSI-RPL-04) 11, Contingency Plan (KSI-RPL-01) 12. Combined Tabletop Test Report (KSI-RPL-01) 13. RTO RPO Definitions (KSI-RPL-01) 14. contingency plan test report (KSI-RPL-04) | K12: Partial | L12: N/A - All requirements met
A13: Incident Reporting | B13: KSI-INR | C13: Incident Reporting | D13: A secure cloud service offering will document, report, and analyze security incidents to ensure regulatory compliance and continuous security improvement. | E13: Verify incident reporting procedures, logging capabilities, and lessons learned processes | F13: The KSI-INR testing methods are outlined in the KSI Requirements tab of this workbook. Those details describe the Fortreum assessment decisions for this KSI objective. | G13: AWS Logs, AWS SecurityHub https://meridian-knowledge-solutions.github.io/fedramp_20x_public_submission_live/ | H13: Partially Automated | I13: Determination: Based on the KSI validation requirement, Fortreum determined that Meridian established a structured and policy-driven incident response program aligned with FedRAMP requirements. Incident reporting procedures are documented, including timelines, roles, and communication protocols, and are supported by tabletop exercises and after-action reports. Security incidents are logged and reviewed regularly, with pattern analysis and trend reports informing continuous improvement. Security Hub insights support incident tracking and log group configurations. After-action reports and lessons learned are maintained, although integration into operational updates could be strengthened. Overall, the environment supports effective incident detection, reporting, and response, with opportunities to enhance automation and operational feedback loops. | J13: 1. failed_ksi_Report_readable.md (git/validation folder) 2. continuous_ksi_results.json (git/results folder) 3. ksi_rules:KSI-INC.01.md (docs/ksi_rules) 4. KSI-INC.01-cli_output.json (KSI-INC.01) 5. ksi_rules:KSI-INC.02.md (docs/ksi_rules) 6. KSI-INC.02-cli_output.json (KSI-INC.02) 7. ksi_rules:KSI-INC.03.md (docs/ksi_rules) 8. KSI-INC.03-cli_output.json (KSI-INC.03) 9. ksi_rules:KSI-INC.04.md (docs/ksi_rules) 10. contingency plan test report (KSI-INC-04) 11. Combined Tabletop Test Report (KSI-INC-01) 12. After Action Report and Lessons Learned (KSI-INR-03) 13. Incident Tracking and Pattern Analysis System KSI-INR-02) | K13: TRUE | L13: N/A - All requirements met

Sheet KSI Requirements
A1: KSI Requirements Validation Details
A3: KSI ID | B3: KSI Name | C3: Requirement ID | D3: Requirement Text | E3: CSP Automated Validation Tools | F3: Automation Status | G3: 3PAO Observations/Test Results/Findings | H3: Validation Status | I3: Evidence
A4: KSI-CNA - Cloud Native Architecture
A5: KSI-CNA | B5: Cloud Native Architecture | C5: KSI-CNA-01 | D5: A secure cloud service offering will utilize cloud-native architecture and design principles to enforce and enhance the confidentiality, Integrity, and Availability of the system. Cloud service providers MUST: 01: Configure ALL information resources to limit inbound and outbound traffic. | E5: aws ec2 describe-security-groups --output json Analyze security groups for comprehensive ingress AND egress traffic controls aws ec2 describe-network-acls --output json Check Network ACLs for subnet-level traffic filtering (defense in depth) aws ec2 describe-route-tables --output json Validate route tables for controlled traffic routing and egress paths aws ec2 describe-nat-gateways --output json Check NAT Gateways for controlled egress traffic from private subnets aws ec2 describe-vpc-endpoints --output json Validate VPC endpoints for private service access (avoiding internet routing) aws wafv2 list-web-acls --scope REGIONAL --output json Check WAF for application-layer traffic filtering and protection aws elbv2 describe-load-balancers --output json Analyze load balancers for traffic distribution and access controls aws logs describe-log-groups --log-group-name-prefix /aws/vpc/flowlogs --output json Verify VPC Flow Logs for traffic monitoring and visibility (CloudWatch destination) | F5: Fully Automated | G5: Determination: Automation Results: PASS Strong multi-layer traffic controls (84%): PASS VPC infrastructure: 1 VPC(s) detected PASS Strong ingress controls: 13/14 security groups are restrictive FAIL Minimal egress controls: 1/14 security groups control outbound traffic PASS Default security group is properly secured PASS Custom network controls: 1/1 Network ACLs with custom traffic filtering rules PASS Controlled egress routing: 1 private route table with NAT gateway routing PASS Managed egress: 1 NAT gateway for controlled outbound access PASS Private service access: 7 VPC endpoints reduce internet-bound traffic PASS Application-layer protection: 1 WAF Web ACLs configured PASS Traffic distribution: 1 load balancer (1 public, 0 internal) PASS Traffic visibility: 1 VPC Flow Log group for traffic monitoring Manual Testing: None | H5: PARTIAL | I5: Examined: 1. failed_ksi_Report_readable.md (git/validation folder) 2. continuous_ksi_results.json (git/results folder) 3. ksi_rules:KSI-CNA.01.md (docs/ksi_rules) Tested: 1. Validated KSI-CNA.01-cli_output.json (KSI-CNA.01)
A6: KSI-CNA | B6: Cloud Native Architecture | C6: KSI-CNA-02 | D6: Automation Results: PASS Excellent attack surface minimization and lateral movement prevention (85%): PASS Strong attack surface minimization: 6/8 private subnets (75%) PASS Good AZ segmentation: 8 subnets across 2 availability zones PASS Strong micro-segmentation: 13/14 custom security groups PASS Lateral movement barriers: 7/14 security groups with specific rules PASS Minimal compute exposure: 4/4 instances in private subnets PASS Database isolation: All 1 RDS instances private PASS Controlled service exposure: Single internet-facing load balancer with private backend services PASS Lambda isolation: 1/3 functions in VPC PASS Advanced segmentation barriers: 1/1 Network ACLs with custom isolation rules Manual Testing: None | E6: aws cloudformation list-stacks --stack-status-filter CREATE_COMPLETE UPDATE_COMPLETE UPDATE_ROLLBACK_COMPLETE --output json Check CloudFormation stacks for immutable infrastructure deployment foundation aws ec2 describe-launch-templates --max-items 50 --output json Validate launch templates for immutable instance deployments with versioning aws ecr describe-repositories --max-items 50 --output json Assess ECR repositories for immutable container image deployments aws lambda list-functions --max-items 50 --output json Check Lambda functions for immutable serverless deployment patterns aws autoscaling describe-auto-scaling-groups --max-items 50 --output json Evaluate Auto Scaling Groups for immutable scaling patterns using launch templates aws ecs list-services --max-items 50 --output json 2>/dev/null || echo '{"serviceArns": []}' Check ECS services for immutable container orchestration (graceful fallback) aws deploy list-applications --output json Assess CodeDeploy applications for automated immutable deployment patterns aws elbv2 describe-target-groups --max-items 50 --output json Check load balancer target groups for blue/green immutable deployment infrastructure aws configservice describe-config-rules --output json Evaluate Config rules for immutable deployment compliance and governance aws organizations describe-organization --output json 2>/dev/null || echo '{"Organization": null}' Check for enterprise-wide immutable deployment governance through AWS Organizations | F6: Fully Automated | G6: Determination: Automation Results: PASS Excellent attack surface minimization and lateral movement prevention (85%): PASS Strong attack surface minimization: 6/8 private subnets (75%) PASS Good AZ segmentation: 8 subnets across 2 availability zones PASS Strong micro-segmentation: 13/14 custom security groups PASS Lateral movement barriers: 7/14 security groups with specific rules PASS Minimal compute exposure: 4/4 instances in private subnets PASS Database isolation: All 1 RDS instances private PASS Controlled service exposure: Single internet-facing load balancer with private backend services PASS Lambda isolation: 1/3 functions in VPC PASS Advanced segmentation barriers: 1/1 Network ACLs with custom isolation rules Manual Testing: None | H6: TRUE | I6: Examined: 1. failed_ksi_Report_readable.md (git/validation folder) 2. continuous_ksi_results.json (git/results folder) 3. ksi_rules:KSI-CNA.02.md (docs/ksi_rules) Tested: 1. Validated KSI-CNA.02-cli_output.json (KSI-CNA.02)
A7: KSI-CNA | B7: Cloud Native Architecture | C7: KSI-CNA-03 | D7: A secure cloud service offering will utilize cloud-native architecture and design principles to enforce and enhance the confidentiality, Integrity, and Availability of the system. 02: Design systems to minimize the attack surface and minimize lateral movement if compromised. | E7: aws ec2 describe-subnets --output json Analyze subnet segmentation for attack surface isolation (public vs private) aws ec2 describe-security-groups --output json Evaluate micro-segmentation and lateral movement prevention through security group rules aws ec2 describe-instances --output json Assess compute workload exposure and placement for attack surface minimization aws ec2 describe-network-acls --output json Check Network ACLs for subnet-level isolation and lateral movement barriers aws elbv2 describe-load-balancers --output json Analyze load balancer exposure patterns (internal vs internet-facing) aws lambda list-functions --output json Assess Lambda function isolation and VPC configuration for attack surface reduction aws rds describe-db-instances --output json Check database placement and exposure (should be in private subnets) | F7: Fully Automated | G7: Determination: Automation Results: PASS Comprehensive logical networking for traffic flow control (106%): PASS Logical routing infrastructure: 5/5 route tables with intentional traffic flows PASS Advanced routing patterns: 4 route tables with custom traffic control PASS Advanced network access control: 1/1 NACLs with custom traffic flow policies PASS Advanced service routing: 7 VPC endpoints (1 gateway, 4 interface, 2 GWLB) PASS Single-VPC architecture: No Transit Gateways needed (appropriate design) PASS Application-layer traffic control: 1 Application Load Balancers PASS Controlled egress routing: 1 active NAT Gateways PASS Traffic flow monitoring: 1 VPC Flow Log groups Manual Testing: None | H7: TRUE | I7: Examined: 1. failed_ksi_Report_readable.md (git/validation folder) 2. continuous_ksi_results.json (git/results folder) 3. ksi_rules:KSI-CNA.03.md (docs/ksi_rules) Tested: 1. Validated KSI-CNA.03-cli_output.json (KSI-CNA.03)
A8: KSI-CNA | B8: Cloud Native Architecture | C8: KSI-CNA-04 | D8: A secure cloud service offering will utilize cloud native architecture and design principles to enforce and enhance the confidentiality, Integrity, and Availability of the system. 04: Use immutable infrastructure with strictly defined functionality and privileges by default. | E8: aws ec2 describe-instances --query 'Reservations[*].Instances[*].[InstanceId,Tags,LaunchTime,ImageId]' --output json Analyze instance patterns for Terraform-managed immutable deployments (consistent tagging, recent launches) aws ec2 describe-launch-templates --output json Check launch templates for standardized, versioned instance deployment patterns aws autoscaling describe-auto-scaling-groups --output json Validate Auto Scaling Groups for instance replacement patterns (immutable scaling) aws ec2 describe-images --owners self --output json Check custom AMIs for versioned machine image pipeline (immutable base images) aws lambda list-functions --output json Validate serverless functions (immutable compute even in VM-focused architectures) aws s3api list-buckets --query 'Buckets[?contains(Name, terraform) || contains(Name, tfstate)]' --output json Detect Terraform state management patterns (S3 backend indicates mature IaC) aws dynamodb list-tables --output json Check for Terraform state locking tables (DynamoDB indicates advanced IaC patterns) aws codebuild list-projects --output json Check for CI/CD build projects (AMI pipelines, Terraform automation) aws ssm describe-parameters --output json Validate Systems Manager parameters for configuration management and versioning | F8: Fully Automated | G8: Determination: Automation Results: PASS Comprehensive Terraform-managed immutable infrastructure (62%): PASS Infrastructure as Code deployment: 4/4 instances with standardized deployment patterns PASS Immutable deployment patterns: 4/4 instances recently deployed (< 6 months) PASS Consistent naming patterns: 4/4 instances follow standardized naming PASS Serverless functions: 3 Lambda functions (inherently immutable) INFO No launch templates found INFO No Auto Scaling Groups found Manual Testing: None | H8: TRUE | I8: Examined: 1. failed_ksi_Report_readable.md (git/validation folder) 2. continuous_ksi_results.json (git/results folder) 3. ksi_rules:KSI-CNA.04.md (docs/ksi_rules) Tested: 1. Validated KSI-CNA.04-cli_output.json (KSI-CNA.04)
A9: KSI-CNA | B9: Cloud Native Architecture | C9: KSI-CNA-05 | D9: A secure cloud service offering will utilize cloud native architecture and design principles to enforce and enhance the confidentiality, Integrity, and Availability of the system. 05: Have denial of service protection. | E9: Check AWS Shield Advanced subscription for premium DDoS protection and response team aws wafv2 list-web-acls --scope REGIONAL --output json Validate WAF for application-layer DDoS protection and rate limiting aws wafv2 list-web-acls --scope CLOUDFRONT --output json Check CloudFront WAF for edge-based application protection aws cloudfront list-distributions --output json Verify CloudFront distributions for edge-based DDoS protection and traffic distribution aws elbv2 describe-load-balancers --output json Check load balancers for traffic distribution and DDoS mitigation capabilities aws autoscaling describe-auto-scaling-groups --output json Validate Auto Scaling Groups for capacity-based DDoS mitigation aws route53 list-hosted-zones --output json Check Route 53 for DNS-layer protection and traffic routing capabilities aws cloudwatch describe-alarms --output json Verify CloudWatch alarms for DDoS detection and automated response | F9: Fully Automated | G9: Determination: Automation Results: PASS Comprehensive DoS protection established (94%): PASS Network-layer protection: AWS Shield Standard (automatic DDoS protection) PASS Application-layer protection: 1 Regional WAF Web ACL(s) - meridian-waf-acl PASS Service resilience: 1 multi-AZ load balancer(s) providing traffic distribution PASS Internal DNS resilience: 1 private Route 53 hosted zone(s) Manual Testing: None | H9: PARTIAL | I9: Examined: 1. failed_ksi_Report_readable.md (git/validation folder) 2. continuous_ksi_results.json (git/results folder) 3. ksi_rules:KSI-CNA.05.md (docs/ksi_rules) Tested: 1. Validated KSI-CNA.05-cli_output.json (KSI-CNA.05)
A10: KSI-CNA | B10: Cloud Native Architecture | C10: KSI-CNA-06 | D10: A secure cloud service offering will utilize cloud native architecture and design principles to enforce and enhance the confidentiality, Integrity, and Availability of the system. 06: Design systems for high availability and rapid recovery. | E10: aws ec2 describe-subnets --output json Analyze subnet distribution across availability zones for network-level HA aws ec2 describe-availability-zones --output json Check available AZs in region for HA planning and validation aws rds describe-db-instances --output json Validate RDS Multi-AZ deployments and database high availability aws elbv2 describe-load-balancers --output json Check load balancers for application-layer HA and traffic distribution aws autoscaling describe-auto-scaling-groups --output json Validate Auto Scaling Groups for compute resilience and multi-AZ distribution aws backup list-backup-plans --output json Check backup plans for data protection and recovery capabilities aws ec2 describe-snapshots --owner-ids self --output json Validate EBS snapshot strategy for storage recovery aws s3api list-buckets --output json Check S3 buckets for storage redundancy and cross-region replication aws route53 list-hosted-zones --output json Validate DNS redundancy and health check capabilities | F10: Fully Automated | G10: Determination: Automation Results: PASS Excellent high availability design for pilot environment (100%): PASS Strong network HA: 8 subnets across 2 AZs PASS Balanced subnet distribution across availability zones PASS Application HA: 1 multi-AZ load balancer(s) providing traffic distribution PASS Active backup strategy: 1 AWS Backup plan(s) with recent execution PASS Storage redundancy: 2 S3 bucket(s) with built-in 11-9s durability PASS Database HA-ready: 1 RDS instance(s) with multi-AZ subnet groups (easily convertible) INFO Compute HA via Infrastructure as Code (Terraform-managed instances acceptable for pilot) PASS Storage recovery via centralized AWS Backup (may include EBS snapshots) PASS DNS infrastructure: 1 Route 53 hosted zone(s) Manual Testing: None | H10: TRUE | I10: Examined: 1. failed_ksi_Report_readable.md (git/validation folder) 2. continuous_ksi_results.json (git/results folder) 3. ksi_rules:KSI-CNA.06.md (docs/ksi_rules) Tested: 1. Validated KSI-CNA.06-cli_output.json (KSI-CNA.06)
A11: KSI-CNA | B11: Cloud Native Architecture | C11: KSI-CNA-07 | D11: A secure cloud service offering will utilize cloud native architecture and design principles to enforce and enhance the confidentiality, Integrity, and Availability of the system. 07: Ensure cloud-native information resources are implemented based on host provider's best practices and documented guidance. | E11: aws configservice describe-config-rules --output json Check AWS Config rules for compliance monitoring and best practice enforcement aws cloudtrail describe-trails --output json Validate CloudTrail configuration (security and operational excellence best practice) aws cloudtrail get-trail-status --name $(aws cloudtrail describe-trails --query 'trailList[0].Name' --output text) --output json 2>/dev/null || echo '{"IsLogging":false}' Check CloudTrail logging status (critical for accurate security assessment) aws kms list-keys --output json Check KMS key management (security best practice for encryption) aws iam get-account-summary --output json Analyze IAM configuration patterns (security best practices) aws ec2 describe-instances --output json Evaluate instance configuration for best practices (performance, reliability) aws elbv2 describe-load-balancers --output json Check load balancer implementation (reliability best practices) aws autoscaling describe-auto-scaling-groups --output json Validate Auto Scaling implementation (reliability and cost optimization) aws s3api list-buckets --output json Check S3 usage patterns (cost optimization and security best practices) aws cloudwatch describe-alarms --output json Validate monitoring implementation (operational excellence best practices) aws backup list-backup-plans --output json Check backup strategies (reliability best practices) aws organizations describe-organization --output json 2>/dev/null || echo '{"Organization":null}' Check AWS Organizations setup (governance and operational excellence best practices) | F11: Fully Automated | G11: Determination: Automation Results: PASS Excellent AWS best practices implementation (95%): PASS CloudTrail excellently configured: 'meridianks-Management-events' ready for activation (cost-optimized for pilot) PASS Multi-region audit coverage: CloudTrail spans all AWS regions PASS Log integrity protection: CloudTrail log file validation enabled PASS Encrypted audit logs: CloudTrail using KMS encryption PASS Global service monitoring: CloudTrail capturing global AWS events PASS Real-time log analysis: CloudTrail integrated with CloudWatch Logs PASS Enterprise governance: Organization-wide CloudTrail PASS Encryption key management: 11 KMS keys for data protection PASS IAM best practices: 55 roles vs 2 users (service-oriented architecture) PASS Excellent reliability architecture: 1/1 load balancers multi-AZ PASS Infrastructure as Code scaling: 4/4 Terraform-managed instances (superior to ASGs for pilot) PASS Active data protection: 1 backup plan(s) with recent execution PASS Performance optimization: 4/4 instances using modern types PASS Storage optimization: 2 S3 buckets (cost-effective storage) PASS Monitoring foundation ready: CloudWatch available (alarms optional for pilot environments) PASS Compliance service available: AWS Config ready for rule deployment (optional for pilot) PASS Enterprise governance: AWS Organizations with centralized management Manual Testing: None | H11: TRUE | I11: Examined: 1. failed_ksi_Report_readable.md (git/validation folder) 2. continuous_ksi_results.json (git/results folder) 3. ksi_rules:KSI-CNA.07.md (docs/ksi_rules) Tested: 1. Validated KSI-CNA.07-cli_output.json (KSI-CNA.07)
A12: KSI-SVC - Service Configuration
A13: KSI-SVC | B13: Service Configuration | C13: KSI-SVC-01 | D13: A secure cloud service off erring will enforce the use of approved cryptography, continuously verify component integrity, and restrict access to external services. 01:Harden and review network and system configurations | E13: aws ec2 describe-security-groups --output json Check security group configurations for network hardening and access control validation aws ec2 describe-instances --output json Review instance configurations and security settings for system hardening assessment aws ec2 describe-network-acls --output json Analyze Network ACLs for subnet-level traffic filtering and defense-in-depth validation aws config describe-config-rules --output json Check AWS Config rules for automated configuration compliance and hardening validation aws guardduty list-detectors --output json Validate GuardDuty threat detection service enablement for network and system security monitoring aws wafv2 list-web-acls --scope REGIONAL --output json Check Web Application Firewall configuration for application-layer hardening and protection aws ssm describe-patch-baselines --output json Analyze patch management baselines for systematic security updates and vulnerability remediation aws ssm describe-instance-information --output json Check Systems Manager coverage for centralized system configuration management and compliance aws inspector2 get-configuration --output json Validate Amazon Inspector for automated security assessments and vulnerability scanning aws organizations describe-organization --output json Check enterprise-wide security policies and organizational hardening standards across accounts | F13: Fully Automated | G13: Determination: Automation Results: PASS Production-ready multi-layer defense and automated compliance (72%): PASS Network hardening foundation: 14 security groups (14 hardened, 0 require review) PASS System configuration management: 4 instances configured PASS Comprehensive system management: 4/4 instances under SSM (100% coverage) PASS Automated patch management: 17 patch baselines configured INFO Config service available but no rules configured INFO 1 default Network ACLs (consider custom rules for enhanced security) PASS Threat detection enabled: 1 GuardDuty detectors monitoring for threats PASS Application layer protection: 1 Web ACLs configured PASS Enterprise-wide security governance: AWS Organizations enables centralized hardening policies PASS Advanced organization features: SCPs and advanced governance capabilities enabled Manual Testing: None | H13: TRUE | I13: Examined: 1. failed_ksi_Report_readable.md (git/validation folder) 2. continuous_ksi_results.json (git/results folder) 3. ksi_rules:KSI-SVC.01.md (docs/ksi_rules) Tested: 1. Validated KSI-SVC.01-cli_output.json (KSI-SVC.01)
A14: KSI-SVC | B14: Service Configuration | C14: KSI-SVC-02 | D14: A secure cloud service off erring will enforce the use of approved cryptography, continuously verify component integrity, and restrict access to external services. 02: Encrypt or otherwise secure network traffic. | E14: aws ec2 describe-security-groups --output json Check security group configurations for network hardening and access control validation aws ec2 describe-instances --output json Review instance configurations and security settings for system hardening assessment aws ec2 describe-network-acls --output json Analyze Network ACLs for subnet-level traffic filtering and defense-in-depth validation aws config describe-config-rules --output json Check AWS Config rules for automated configuration compliance and hardening validation aws guardduty list-detectors --output json Validate GuardDuty threat detection service enablement for network and system security monitoring aws wafv2 list-web-acls --scope REGIONAL --output json Check Web Application Firewall configuration for application-layer hardening and protection aws ssm describe-patch-baselines --output json Analyze patch management baselines for systematic security updates and vulnerability remediation aws ssm describe-instance-information --output json Check Systems Manager coverage for centralized system configuration management and compliance aws inspector2 get-configuration --output json Validate Amazon Inspector for automated security assessments and vulnerability scanning aws organizations describe-organization --output json Check enterprise-wide security policies and organizational hardening standards across accounts | F14: Fully Automated | G14: Determination: Automation Results: PASS Production-ready multi-layer traffic encryption and certificate management (65%): PASS Load balancer encryption capability: 1 load balancers configured for traffic encryption PASS Private service communication: 7 VPC endpoints (4 interface, 1 gateway) INFO No load balancer listeners configured INFO No CloudFront distributions for global traffic encryption PASS API encryption capability: 1 API Gateway endpoints (HTTPS by default) PASS Database encryption capability: 1 RDS instances (0 with encrypted storage) INFO No ElastiCache clusters for cache encryption PASS Automated certificate management: 2/2 active ACM certificates (100% healthy) INFO No VPN connections for hybrid connectivity encryption PASS Enterprise-wide encryption governance: AWS Organizations enables centralized traffic encryption policies PASS Advanced organization features: SCPs for encryption policy enforcement enabled Manual Testing: None | H14: TRUE | I14: Examined: 1. failed_ksi_Report_readable.md (git/validation folder) 2. continuous_ksi_results.json (git/results folder) 3. ksi_rules:KSI-SVC.02.md (docs/ksi_rules) Tested: 1. Validated KSI-SVC.02-cli_output.json (KSI-SVC.02)
A15: KSI-SVC | B15: Service Configuration | C15: KSI-SVC-03 | D15: A secure cloud service off erring will enforce the use of approved cryptography, continuously verify component integrity, and restrict access to external services. 03: Encrypt all federal and sensitive information at rest | E15: aws s3api list-buckets --output json Get S3 buckets for object storage encryption validation and federal data protection aws ec2 describe-volumes --output json Check EBS volume encryption status for block storage and instance data protection aws rds describe-db-instances --output json Validate RDS database encryption for structured data at rest and backup encryption aws rds describe-db-snapshots --owner-type self --output json Check RDS snapshot encryption for database backup and recovery data protection aws efs describe-file-systems --output json Check Elastic File System encryption for shared storage and distributed application data aws backup list-backup-vaults --output json Validate AWS Backup vault encryption for centralized backup data protection and compliance aws kms list-keys --output json Check KMS key management for enterprise encryption key governance and automated key rotation | F15: Fully Automated | G15: Determination: Automation Results: PASS Advanced at-rest encryption across multiple storage services (45%): PASS Object storage encryption: 2 S3 buckets configured (encryption validation requires bucket-level check) PASS Block storage encryption: 8/8 EBS volumes encrypted (100%) PASS Database encryption: 1/1 RDS instances encrypted (100%) PASS Backup encryption: 2/2 backup vaults encrypted (100%) PASS Encryption key infrastructure: 12 KMS keys (0 customer-managed, 12 AWS-managed) INFO Single-account deployment (appropriate for pilot/development) Manual Testing: None | H15: TRUE | I15: Examined: 1. failed_ksi_Report_readable.md (git/validation folder) 2. continuous_ksi_results.json (git/results folder) 3. ksi_rules:KSI-SVC.03.md (docs/ksi_rules) Tested: 1. Validated KSI-SVC.03-cli_output.json (KSI-SVC.03)
